Workbook
Name B_Cash: 't-accounts month 2'!$B$68
Name B_Cash: #REF!

Sheet General Ledger
A1: Company Name | C1: Reial Club De Padel Roldans | G1: General Ledger | K1: Assets / Expenses / Dividend | N1: Liabilities / OE / Revenues | V1: Account Type | X1: Account Name
A2: Address | K2: Debit | L2: Credit | N2: Debit | O2: Credit | V2: Assets | X2: Cash
A3: Report date | K3: Increase | L3: Decrease | N3: Decrease | O3: Increase | V3: Liabilities
B4: 44562 | V4: Owners Equity
A5: General Ledger Report | V5: Revenue | X5: List of accounts | Y5: Code | Z5: Financial Statement | AA5: Group | AB5: Sub-Group | AC5: Normally
A6: Date | B6: Account Type | C6: GL Account Name | D6: GL Account # | E6: Vendor / Client | H6: Debit | I6: Credit | V6: Expense | X6: Bank checking account | Y6: 1000 | Z6: Balance sheet | AA6: Current assets | AB6: Cash and cash equivalents | AC6: Debit
A7: Creation of the company, received investment from investors | X7: Bank savings account | Y7: 1010 | Z7: Balance sheet | AA7: Current assets | AB7: Cash and cash equivalents | AC7: Debit
A8: 44927 | B8: Assets | C8: Cash | H8: 200000
B9: Owners Equity | C9: Capital Stock | I9: 200000 | X9: Online savings account | Y9: 1020 | Z9: Balance sheet | AA9: Current assets | AB9: Cash and cash equivalents | AC9: Debit
A10: We buy all the paddel courts in order for them to be ready on day 2, they ask us in advantace to pay 30% in cash, the rest after the courts are build | X10: Petty cash account | Y10: 1030 | Z10: Balance sheet | AA10: Current assets | AB10: Cash and cash equivalents | AC10: Debit
A11: 44927 | B11: Assets | C11: Prepaid Courts | H11: 36000 | X11: Paypal account | Y11: 1040 | Z11: Balance sheet | AA11: Current assets | AB11: Cash and cash equivalents | AC11: Debit
B12: Assets | C12: Cash | I12: 36000 | X12: Accounts receivable | Y12: 1200 | Z12: Balance sheet | AA12: Current assets | AB12: Accounts receivable | AC12: Debit
A13: We pay the rent of the building at the beggining of the month. | X13: Gifts & samples | Y13: 5030 | Z13: Income Statement | AA13: Expense | AB13: Sales and marketing | AC13: Debit
A14: 44927 | B14: Assets | C14: Prepaid building rent | H14: 5700
B15: Assets | C15: Cash | I15: 5700
A16: We buy padel material to loan as a service to customers. (10 packs of balls to loan and 10 rackets to loan)
A17: 44927 | B17: Assets | C17: Padel Equipment | D17: €35 each racket | E17: €5 each pack | H17: 400
B18: Assets | C18: Cash | I18: 400
A19: We buy all padel material to sell in our store to customers. (50 packs of balls and 20 rackets)
A20: 44927 | B20: Assets | C20: Padel Equipment Inventory | D20: €35 each racket | E20: €5 each pack | H20: 950
B21: Assets | C21: Cash | I21: 950
A22: We buy padel equipment for coaches. | X22: Research and development | Y22: 4800 | Z22: Income Statement | AA22: Expense | AB22: Research and development | AC22: Debit
A23: 44927 | B23: Assets | C23: Padel equipment for coaches | H23: 250 | X23: Sales commissions | Y23: 5000 | Z23: Income Statement | AA23: Expense | AB23: Sales and marketing | AC23: Debit
B24: Assets | C24: Cash | I24: 250 | X24: Sales promotion | Y24: 5010 | Z24: Income Statement | AA24: Expense | AB24: Sales and marketing | AC24: Debit
A25: Purchaese of Towels for members at €3 each. We buy 100 towels, we calculate that the first month we will sell 80 | X25: Advertising | Y25: 5020 | Z25: Income Statement | AA25: Expense | AB25: Sales and marketing | AC25: Debit
A26: 44927 | B26: Assets | C26: Towels for members | H26: 300 | X26: Gifts & samples | Y26: 5030 | Z26: Income Statement | AA26: Expense | AB26: Sales and marketing | AC26: Debit
B27: Cash | C27: Cash | I27: 300
A28: The courts are now build, we pay what we owe with cash.
A29: 44928 | B29: Assets | C29: Prepaid Courts | I29: 36000
B30: Assets | C30: Cash | I30: 84000
B31: Assets | C31: Courts | H31: 120000
A32: Revenue from an entrire week of court renting service. We have an average of 120 persons / day, and depending on their membeship levels, the rent is higher or lower.
A33: 44934 | B33: Assets | C33: Cash | H33: 7175
B34: Revenue | C34: Court Member Revenue | I34: 3675
B35: Revenue | C35: Court Revenue | I35: 3500
A36: Revenue from loaned equipment, rackets and balls. Racket: €3/game, Balls: €5/Game.
A37: 44934 | B37: Revenue | C37: Equipment loaned | I37: 275
B38: Assets | C38: Cash | H38: 275
A39: Revenue from sold equipment, rackets and balls. 10 Rackets: €45 each, 20 packs of Balls: €10each.
A40: 44934 | B40: Rervenue | C40: Sales from rackets | I40: 450
...

Sheet COGS
D3: Average cost method (Padel Balls packs) | Q3: Average cost method (Padel rackets) | AD3: Average cost method (towels)
C5: Date | E5: Units | G5: € / Unit | I5: Total | P5: Date | R5: Units | T5: € / Unit | V5: Total | AE5: Date | AG5: Units | AI5: € / Unit | AK5: Total
B7: Beginning inventory | E7: 0 | G7: 0 | I7: 0 | O7: Beginning inventory | R7: 0 | T7: 0 | V7: 0 | AD7: Beginning inventory | AG7: 0 | AI7: 0 | AK7: 0
B9: Purchases | O9: Purchases | AD9: Purchases
C10: 44927 | E10: 50 | G10: 5 | I10: 250 | P10: 44927 | R10: 20 | T10: 35 | V10: =T10*R10 -> 700 | AE10: 44927 | AG10: 100 | AI10: 3 | AK10: =AI10*AG10 -> 300
C12: 44941 | E12: 70 | G12: 4.5 | I12: 315 | J12: 4.71 | P12: 44941 | R12: 30 | T12: 32 | V12: 960 | AE12: 44593 | AG12: 100 | AI12: 3 | AK12: 300
B14: Goods Available for sale | E14: 120 | I14: 565 | J14: Avg. Cost -> 565/120 = 4,71€ | O14: Goods Available for sale | R14: 50 | V14: =V12+V10 -> 1660 | W14: =V14/R14 -> 33.2 | X14: Avg. Cost -> 1400/40 = 33,2€ | AD14: Goods Available for sale | AG14: 200 | AK14: =AK12+AK10 -> 600 | AM14: =AK14/AG14 -> 3 | AN14: Avg. Cost -> 300/100 = 3€
B16: Ending inventory | E16: 10 | I16: =E16*J12 -> 47.1 | J16: Ending inventory -> 10 x 4,71 = 47,10€ | O16: Ending inventory | R16: 3 | V16: =W14*R16 -> 99.6 | W16: Ending inventory -> 10 x 33,2 = 332€ | AD16: Ending inventory | AG16: 0 | AK16: 100 | AM16: Ending inventory -> 0 x 3 = 0€
B18: Cost of goods sold | E18: 110 | I18: =E18*J12 -> 518.1 | J18: Cost of goods sold -> 110 x 4,71 = 518€ | O18: Cost of goods sold | R18: 47 | V18: =W14*R18 -> 1560.4 | W18: Cost of goods sold -> 33,2 x 40 = 1328€ | AD18: Cost of goods sold | AG18: 100 | AK18: =AM14*AG18 -> 300 | AM18: Cost of goods sold -> 100 x 3 = 300
D25: First-in First-out method (Padel Balls) | Q25: First-in First-out method (Padel Rackets)
B27: Date | D27: Beg. Inv | F27: Purchases | H27: End Inv. | J27: CoGS | O27: Date | Q27: Beg. Inv | S27: Purchases | U27: End Inv. | W27: CoGS
AF28: First-in First-out method (Towels)
D29: 0 | Q29: 0
AD30: Date | AF30: Beg. Inv | AH30: Purchases | AJ30: End Inv. | AL30: CoGS
B31: 44562 | F31: 50 at 5€ | H31: 0 | J31: 50 at 5€ | O31: 44562 | S31: 20 at 35€ | U31: 0 | W31: 20 at 35€
AF32: 0
B33: 44576 | F33: 70 at 4,5€ | H33: 10 at 4,5€ | J33: 60 at 4,5€ | O33: 44576 | S33: 30 at 32€ | U33: 3 at 32€ | W33: 27 at 32€
AD34: 44562 | AH34: 100 at 3€ | AJ34: 0 at 3€ | AL34: 100 at 3€
C36: Units | H36: 10 | J36: 110 | P36: Units | U36: 3 | W36: 47 | AD36: 44593 | AH36: 0
C38: Costs | H38: 45 | J38: 520 | P38: Costs | U38: 96 | W38: 1564
AE39: Units | AJ39: 0 | AL39: 100
C40: Cost of goods available for sale | I40: 565 | P40: Cost of goods available for sale | V40: 1660
AE41: Costs | AJ41: 0 | AL41: 300
AE43: Cost of goods available for sale | AK43: 300
D56: Last-in First-out method (Padel Balls) | Q56: Last-in First-out method (Padel Balls) | AF56: Last-in First-out method (Towels)
B58: Date | D58: Beg. Inv | F58: Purchases | H58: End Inv. | J58: CoGS | O58: Date | Q58: Beg. Inv | S58: Purchases | U58: End Inv. | W58: CoGS | AD58: Date | AF58: Beg. Inv | AH58: Purchases | AJ58: End Inv. | AL58: CoGS
D60: 0 | Q60: 0 | AF60: 0
B62: 44562 | F62: 50 at 5€ | H62: 10 at 5€ | J62: 40 at 5€ | O62: 44562 | S62: 20 at 35€ | U62: 3 at 35€ | W62: 17 at 35€ | AD62: 44562 | AH62: 100 at 3€ | AJ62: 0 at 3€ | AL62: 100 at 3€
B64: 44576 | F64: 70 at 4,5€ | H64: 0 | J64: 70 at 4,5€ | O64: 44576 | S64: 30 at 32€ | U64: 0 | W64: 30 at 32€ | AD64: 44593 | AH64: 0
C66: Units | H66: 10 | J66: 110
P67: Units | U67: 3 | W67: 47 | AE67: Units | AJ67: 0 | AL67: 100
C68: Costs | H68: 50 | J68: 515
P69: Costs | U69: 105 | W69: 1555 | AE69: Costs | AJ69: 0 | AL69: 300
C70: Cost of goods available for sale | I70: 565
P71: Cost of goods available for sale | V71: 1660 | AE71: Cost of goods available for sale | AK71: 300

Sheet t-accounts month 1
A1: 1 | B1: DEBIT | C1: CREDIT | E1: =+A1+1 -> 2 | F1: DEBIT | G1: CREDIT | I1: =+E1+1 -> 3 | J1: DEBIT | K1: CREDIT | M1: =+I1+1 -> 4 | N1: DEBIT | O1: CREDIT | Q1: =+M1+1 -> 5 | R1: DEBIT | S1: CREDIT | U1: =+Q1+1 -> 6 | V1: DEBIT | W1: CREDIT | Y1: =+U1+1 -> 7 | Z1: DEBIT | AA1: CREDIT | AD1: =+Y1+1 -> 8 | AE1: DEBIT | AF1: CREDIT | AH1: =+AD1+1 -> 9 | AI1: DEBIT | AJ1: CREDIT | AL1: =+AH1+1 -> 10 | AM1: DEBIT | AN1: CREDIT | AP1: =+AL1+1 -> 11 | AQ1: DEBIT | AR1: CREDIT | AT1: =+AP1+1 -> 12 | AU1: DEBIT | AV1: CREDIT | AX1: =+AT1+1 -> 13 | AY1: DEBIT | AZ1: CREDIT | BB1: =+AX1+1 -> 14 | BC1: DEBIT | BD1: CREDIT | BF1: =+BB1+1 -> 15 | BG1: DEBIT | BH1: CREDIT | BJ1: =+BF1+1 -> 16 | BK1: DEBIT | BL1: CREDIT | BN1: =+BJ1+1 -> 17 | BO1: DEBIT | BP1: CREDIT | BR1: =+BN1+1 -> 18 | BS1: DEBIT | BT1: CREDIT | BV1: =+BR1+1 -> 19 | BW1: DEBIT | BX1: CREDIT | BZ1: =+BV1+1 -> 20 | CA1: DEBIT | CB1: CREDIT | CD1: =+BZ1+1 -> 21 | CE1: DEBIT | CF1: CREDIT | CH1: =+CD1+1 -> 22 | CI1: DEBIT | CJ1: CREDIT | CL1: =+CH1+1 -> 23 | CM1: DEBIT | CN1: CREDIT | CP1: =+CL1+1 -> 24 | CQ1: DEBIT | CR1: CREDIT | CT1: =+CP1+1 -> 25 | CU1: DEBIT | CV1: CREDIT | CX1: =+CT1+1 -> 26 | CY1: DEBIT | CZ1: CREDIT
A2: Date | B2: Cash | E2: Date | F2: Capital Stock | I2: Date | J2: Prepaid Courts | M2: Date | N2: Prepaid building rent | Q2: Date | R2: Padel equipment inventory | U2: Date | V2: Padel equipment for coaches | Y2: Date | Z2: Towels for members | AD2: Date | AE2: Paddle tennis courts | AH2: Date | AI2: Court revenue from memberships | AL2: Date | AM2: Court revenue | AP2: Date | AQ2: Equipment loaned revenue | AT2: Date | AU2: Rent expense | AX2: Date | AY2: Salary expense | BB2: Date | BC2: Training revenue | BF2: Date | BG2: Machine revenue | BJ2: Date | BK2: Membership revenue | BN2: Date | BO2: Sales from rackets | BR2: Date | BS2: Sales from balls | BV2: Date | BW2: Public service expense | BZ2: Date | CA2: Padel Equipment | CD2: Date | CE2: Dep Expense (Padel Court) | CH2: Date | CI2: Accumulated depreciation (Padel Court) | CL2: Date | CP2: Date | CT2: Date | CX2: Date
A3: 44562 | B3: 200000 | E3: 44562 | G3: 200000 | I3: 44562 | J3: 36000 | M3: 44562 | N3: 5700 | Q3: 44562 | R3: 950 | U3: 44562 | V3: 250 | Y3: 44562 | Z3: 300 | AD3: 44563 | AE3: 120000 | AH3: 44569 | AJ3: 3675 | AL3: 44569 | AN3: 3500 | AP3: 44569 | AR3: 275 | AT3: 44592 | AU3: 5700 | AX3: 44592 | AY3: 5100 | BB3: 44592 | BD3: 16200 | BF3: 44592 | BH3: 300 | BJ3: 44592 | BL3: 12000 | BN3: 44569 | BP3: 450 | BR3: 44569 | BT3: 200 | BV3: 44592 | BW3: 4500 | BZ3: 44562 | CA3: 400 | CD3: 44592 | CE3: 500 | CH3: 44592 | CJ3: 500
A4: 44562 | C4: 36000 | I4: 44563 | K4: 36000 | M4: 44592 | O4: 5700 | Q4: 44562 | R4: 300 | Y4: eliminar | AH4: 44576 | AJ4: 3675 | AL4: 44576 | AN4: 3500 | AP4: 44576 | AR4: 275 | AX4: 44592 | AY4: 2600 | BN4: 44576 | BP4: 450 | BR4: 44576 | BT4: 200
A5: 44562 | C5: 5700 | Q5: 44576 | R5: 1275 | AH5: 44583 | AJ5: 3675 | AL5: 44583 | AN5: 3500 | AP5: 44583 | AR5: 275 | AX5: 44592 | AY5: 6000 | BN5: 44583 | BP5: 450 | BR5: 44583 | BT5: 200
A6: 44562 | C6: 400 | AH6: 44590 | AJ6: 3675 | AL6: 44590 | AN6: 3500 | AP6: 44590 | AR6: 275 | BN6: 44590 | BP6: 450 | BR6: 44590 | BT6: 200
A7: 44562 | C7: 950
A8: 44562 | C8: 250
A9: 44562 | C9: 300
A10: 44562 | C10: 84000
A11: 44569 | B11: 7175
A12: 44569 | B12: 275
A13: 44569 | B13: 650
A14: 44941 | C14: 1275
A15: 44576 | B15: 7175
A16: 44576 | B16: 275
A17: 44577 | B17: 650
A18: 44583 | B18: 7175
A19: 44583 | B19: 275
A20: 44583 | B20: 650
A21: 44590 | B21: 7175
A22: 44590 | B22: 275
A23: 44590 | B23: 650
A24: 44592 | C24: 5100
A25: 44592 | C25: 2600
A26: 44592 | C26: 6000
A27: 44592 | B27: 16200
A28: 44592 | B28: 300
A29: 44592 | B29: 12000
A30: 44592 | C30: 4500
A32: SUM | B32: =SUM(B3:B29) -> 260900 | C32: =SUM(C4:C30) -> 147075
A35: TOTAL | B35: =SUM(B32-C32) -> 113825 | E35: TOTAL | G35: 200000 | I35: TOTAL | K35: 0 | M35: TOTAL | O35: 0 | Q35: TOTAL | R35: =SUM(R3:R5) -> 2525 | U35: TOTAL | V35: 250 | Y35: TOTAL | Z35: 300 | AD35: TOTAL | AE35: 120000 | AH35: TOTAL | AJ35: =SUM(AJ3:AJ6) -> 14700 | AL35: TOTAL | AN35: =SUM(AN3:AN6) -> 14000 | AP35: TOTAL | AR35: =SUM(AR3:AR6) -> 1100 | AT35: TOTAL | AU35: 5700 | AX35: TOTAL | AY35: =SUM(AY3:AY5) -> 13700 | BB35: TOTAL | BD35: 16200 | BF35: TOTAL | BH35: 300 | BJ35: TOTAL | BL35: 12000 | BN35: TOTAL | BP35: =SUM(BP3:BP6) -> 1800 | BR35: TOTAL | BT35: =SUM(BT3:BT6) -> 800 | BV35: TOTAL | BW35: 4500 | BZ35: TOTAL | CA35: 400 | CD35: TOTAL | CE35: 500 | CH35: TOTAL | CJ35: 500

Sheet t-accounts month 2
A1: 1 | B1: DEBIT | C1: CREDIT | E1: =+A1+1 -> 2 | F1: DEBIT | G1: CREDIT | I1: =+E1+1 -> 3 | J1: DEBIT | K1: CREDIT | M1: =+#REF!+1 -> #REF! | N1: DEBIT | O1: CREDIT | Q1: =+M1+1 -> #REF! | R1: DEBIT | S1: CREDIT | U1: =+Q1+1 -> #REF! | V1: DEBIT | W1: CREDIT | Y1: =+U1+1 -> #REF! | Z1: DEBIT | AA1: CREDIT | AC1: =+Q1+1 -> #REF! | AD1: DEBIT | AE1: CREDIT | AG1: =+AC1+1 -> #REF! | AH1: DEBIT | AI1: CREDIT | AK1: =+AG1+1 -> #REF! | AL1: DEBIT | AM1: CREDIT | AO1: =+AK1+1 -> #REF! | AP1: DEBIT | AQ1: CREDIT | AS1: =+AO1+1 -> #REF! | AT1: DEBIT | AU1: CREDIT | AW1: =+AS1+1 -> #REF! | AX1: DEBIT | AY1: CREDIT | BA1: =+AW1+1 -> #REF! | BB1: DEBIT | BC1: CREDIT | BE1: =+#REF!+1 -> #REF! | BF1: DEBIT | BG1: CREDIT | BI1: =+BE1+1 -> #REF! | BJ1: DEBIT | BK1: CREDIT | BM1: =+BI1+1 -> #REF! | BN1: DEBIT | BO1: CREDIT | BQ1: =+BM1+1 -> #REF! | BR1: DEBIT | BS1: CREDIT | BU1: =+BQ1+1 -> #REF! | BV1: DEBIT | BW1: CREDIT | BY1: =+BU1+1 -> #REF! | BZ1: DEBIT | CA1: CREDIT | CC1: =+BY1+1 -> #REF! | CD1: DEBIT | CE1: CREDIT | CG1: =+CC1+1 -> #REF! | CH1: DEBIT | CI1: CREDIT | CK1: =+CG1+1 -> #REF! | CL1: DEBIT | CM1: CREDIT | CO1: =+CK1+1 -> #REF! | CP1: DEBIT | CQ1: CREDIT | CS1: =+CO1+1 -> #REF! | CT1: DEBIT | CU1: CREDIT | CW1: =+CS1+1 -> #REF! | CX1: DEBIT | CY1: CREDIT | DA1: =+CW1+1 -> #REF! | DB1: DEBIT | DC1: CREDIT | DE1: =+DA1+1 -> #REF! | DF1: DEBIT | DG1: CREDIT | DI1: =+DE1+1 -> #REF! | DJ1: DEBIT | DK1: CREDIT | DM1: =+DI1+1 -> #REF! | DN1: DEBIT | DO1: CREDIT | DQ1: =+DM1+1 -> #REF! | DR1: DEBIT | DS1: CREDIT | DU1: =+DQ1+1 -> #REF! | DV1: DEBIT | DW1: CREDIT | DY1: =+DU1+1 -> #REF! | DZ1: DEBIT | EA1: CREDIT | EC1: =+DY1+1 -> #REF! | ED1: DEBIT | EE1: CREDIT | EG1: =+EC1+1 -> #REF! | EH1: DEBIT | EI1: CREDIT | EK1: =+EG1+1 -> #REF! | EL1: DEBIT | EM1: CREDIT | EO1: =+EK1+1 -> #REF! | EP1: DEBIT | EQ1: CREDIT | ES1: =+EO1+1 -> #REF! | ET1: DEBIT | EU1: CREDIT | EW1: =+ES1+1 -> #REF! | EX1: DEBIT | EY1: CREDIT | FA1: =+EW1+1 -> #REF! | FB1: DEBIT | FC1: CREDIT | FE1: =+FA1+1 -> #REF! | FF1: DEBIT | FG1: CREDIT | FI1: =+FE1+1 -> #REF! | FJ1: DEBIT | FK1: CREDIT | FM1: =+FI1+1 -> #REF! | FN1: DEBIT | FO1: CREDIT | FQ1: =+FM1+1 -> #REF! | FR1: DEBIT | FS1: CREDIT | FU1: =+FQ1+1 -> #REF! | FV1: DEBIT | FW1: CREDIT | FY1: =+FU1+1 -> #REF! | FZ1: DEBIT | GA1: CREDIT | GC1: =+FY1+1 -> #REF! | GD1: DEBIT | GE1: CREDIT | GG1: =+GC1+1 -> #REF! | GH1: DEBIT | GI1: CREDIT | GK1: =+GG1+1 -> #REF! | GL1: DEBIT | GM1: CREDIT | GO1: =+GK1+1 -> #REF! | GP1: DEBIT | GQ1: CREDIT | GS1: =+GO1+1 -> #REF! | GT1: DEBIT | GU1: CREDIT
B2: Cash | E2: Date | F2: Towels for members | I2: Date | J2: Prepaid building rent | M2: Date | N2: Court Member Revenue | R2: Court Revenue | U2: Date | V2: Equipment loaned revenue | Y2: Date | Z2: Balls sold | AC2: Date | AD2: Rackets sold | AG2: Date | AH2: Rent expense | AK2: Date | AL2: Salary Expense | AO2: Date | AP2: Training revenue | AS2: Date | AT2: Machine revenue | AW2: Date | AX2: Membership revenue | BA2: Date | BB2: Towels for members expense | BE2: Date | BF2: Public service expense | BI2: Date | BJ2: Padel equipment inventory | BM2: Date | BN2: COGS Racket | BQ2: Date | BR2: COGS Balls | BU2: Date | BV2: COGS Towels | BY2: Date | BZ2: Sales from balls | CC2: Date | CD2: Sales from rackets | CG2: Date | CH2: Dep Expense (Padel Court) | CK2: Date | CL2: Accumulated depreciation (Padel Court) | CO2: Date | CS2: Date | CW2: Date | DA2: Date | DE2: Date | DI2: Date | DM2: Date | DQ2: Date | DU2: Date | DY2: Date | EC2: Date | EG2: Date | EK2: Date | EO2: Date | ES2: Date | EW2: Date | FA2: Date | FE2: Date | FI2: Date | FM2: Date | FQ2: Date | FU2: Date | FY2: Date | GC2: Date | GG2: Date | GK2: Date | GO2: Date | GS2: Date
A3: 44592 | B3: =+'t-accounts month 1'!B35 -> 113825 | E3: 44593 | F3: 0 | I3: 44593 | J3: 5700 | M3: 44600 | O3: 3675 | Q3: 44600 | S3: 3500 | U3: 44600 | W3: 275 | Y3: 44600 | AA3: 10 | AC3: 44600 | AE3: 100 | AG3: 44620 | AH3: 5700 | AK3: 44620 | AL3: 5100 | AO3: 44620 | AQ3: 16200 | AS3: 44620 | AU3: 300 | AW3: 44620 | AY3: 15000 | BA3: 44620 | BB3: 0 | BE3: 44620 | BG3: 0 | BI3: 44592 | BJ3: =+'t-accounts month 1'!R35 -> 2525 | BM3: 44620 | BN3: 1555 | BQ3: 44620 | BR3: 515 | BU3: 44620 | BV3: 300 | BY3: 44600 | CA3: 10 | CC3: 44600 | CE3: 100 | CG3: 31/02/2022 | CH3: 500 | CK3: {=+'t-accounts month 1'!CH3:CJ3} -> 44592 | CL3: 0 | CM3: 500
A4: 44593 | C4: 300 | F4: eliminar | I4: 44620 | K4: 5700 | M4: 44607 | O4: 3675 | Q4: 44607 | S4: 3500 | U4: 44607 | W4: 275 | Y4: 44607 | AA4: 10 | AC4: 44607 | AE4: 100 | AK4: 44620 | AL4: 2600 | BI4: 44593 | BK4: 300 | BY4: 44607 | CA4: 10 | CC4: 44607 | CE4: 100 | CK4: 31/02/2022 | CM4: 500
A5: 44593 | C5: 5700 | M5: 44614 | O5: 3675 | Q5: 44614 | S5: 3500 | U5: 44614 | W5: 275 | Y5: 44614 | AA5: 50 | AC5: 44614 | AE5: 100 | AK5: 44620 | AL5: 6000 | BI5: 44620 | BK5: 1555 | BY5: 44614 | CA5: 50 | CC5: 44614 | CE5: 100
A6: 44600 | B6: 7175 | M6: 44620 | O6: 3675 | Q6: 44620 | S6: 3500 | U6: 44620 | W6: 275 | Y6: 44620 | AA6: 30 | AC6: 44620 | AE6: 50 | BI6: 44620 | BK6: 515 | BY6: 44620 | CA6: 30 | CC6: 44620 | CE6: 50
A7: 44600 | B7: 275
A8: 44600 | B8: 110
A9: 44607 | B9: 7175
A10: 44607 | B10: 275
A11: 44607 | B11: 110
A12: 44614 | B12: 7175
A13: 44614 | B13: 275
A14: 44614 | B14: 150
A15: 44620 | B15: 7175
A16: 44620 | B16: 275
A17: 44620 | C17: 5100
A18: 44620 | C18: 2600
A19: 44620 | C19: 6000
A20: 44620 | B20: 16200
A21: 44620 | B21: 300
A22: 44620 | B22: 15000
A23: 44620 | B23: 0
A24: 44620 | B24: 80
A27: SUM | B27: =SUM(B3:B25) -> 175575 | C27: =SUM(C3:C25) -> 19700
A30: TOTAL | B30: =SUM(B27-C27) -> 155875 | E30: TOTAL | F30: 0 | I30: TOTAL | K30: 0 | M30: TOTAL | O30: =SUM(O3:O6) -> 14700 | Q30: TOTAL | S30: =SUM(S3:S6) -> 14000 | U30: TOTAL | W30: =SUM(W3:W6) -> 1100 | Y30: TOTAL | AA30: =SUM(AA3:AA6) -> 100 | AC30: TOTAL | AE30: =SUM(AE3:AE6) -> 350 | AG30: TOTAL | AH30: 5700 | AK30: TOTAL | AL30: =SUM(AL3:AL5) -> 13700 | AO30: TOTAL | AQ30: 16200 | AS30: TOTAL | AU30: 300 | AW30: TOTAL | AY30: 15000 | BA30: TOTAL | BB30: 0 | BE30: TOTAL | BG30: 0 | BI30: TOTAL | BJ30: =BJ3-SUM(BK5:BK7) -> 455 | BM30: TOTAL | BN30: 1555 | BQ30: TOTAL | BR30: 515 | BU30: TOTAL | BV30: 300 | BY30: TOTAL | CA30: =SUM(CA3:CA6) -> 100 | CC30: TOTAL | CE30: =SUM(CE3:CE6) -> 350 | CG30: TOTAL | CH30: 500 | CK30: TOTAL | CM30: =SUM(CM3:CM4) -> 1000
DV66: =+IF(SUM(DV3:DV65)-SUM(DW3:DW65)>0,SUM(DV3:DV65)-SUM(DW3:DW65),"0") -> 0 | DW66: =+IF(SUM(DV3:DV65)-SUM(DW3:DW65)<0,SUM(DV3:DV65)-SUM(DW3:DW65),"0") -> 0 | DZ66: =+IF(SUM(DZ3:DZ65)-SUM(EA3:EA65)>0,SUM(DZ3:DZ65)-SUM(EA3:EA65),"0") -> 0 | EA66: =+IF(SUM(DZ3:DZ65)-SUM(EA3:EA65)<0,SUM(DZ3:DZ65)-SUM(EA3:EA65),"0") -> 0 | ED66: =+IF(SUM(ED3:ED65)-SUM(EE3:EE65)>0,SUM(ED3:ED65)-SUM(EE3:EE65),"0") -> 0 | EE66: =+IF(SUM(ED3:ED65)-SUM(EE3:EE65)<0,SUM(ED3:ED65)-SUM(EE3:EE65),"0") -> 0 | EH66: =+IF(SUM(EH3:EH65)-SUM(EI3:EI65)>0,SUM(EH3:EH65)-SUM(EI3:EI65),"0") -> 0 | EI66: =+IF(SUM(EH3:EH65)-SUM(EI3:EI65)<0,SUM(EH3:EH65)-SUM(EI3:EI65),"0") -> 0 | EL66: =+IF(SUM(EL3:EL65)-SUM(EM3:EM65)>0,SUM(EL3:EL65)-SUM(EM3:EM65),"0") -> 0 | EM66: =+IF(SUM(EL3:EL65)-SUM(EM3:EM65)<0,SUM(EL3:EL65)-SUM(EM3:EM65),"0") -> 0 | EP66: =+IF(SUM(EP3:EP65)-SUM(EQ3:EQ65)>0,SUM(EP3:EP65)-SUM(EQ3:EQ65),"0") -> 0 | EQ66: =+IF(SUM(EP3:EP65)-SUM(EQ3:EQ65)<0,SUM(EP3:EP65)-SUM(EQ3:EQ65),"0") -> 0 | ET66: =+IF(SUM(ET3:ET65)-SUM(EU3:EU65)>0,SUM(ET3:ET65)-SUM(EU3:EU65),"0") -> 0 | EU66: =+IF(SUM(ET3:ET65)-SUM(EU3:EU65)<0,SUM(ET3:ET65)-SUM(EU3:EU65),"0") -> 0 | EX66: =+IF(SUM(EX3:EX65)-SUM(EY3:EY65)>0,SUM(EX3:EX65)-SUM(EY3:EY65),"0") -> 0 | EY66: =+IF(SUM(EX3:EX65)-SUM(EY3:EY65)<0,SUM(EX3:EX65)-SUM(EY3:EY65),"0") -> 0 | FB66: =+IF(SUM(FB3:FB65)-SUM(FC3:FC65)>0,SUM(FB3:FB65)-SUM(FC3:FC65),"0") -> 0 | FC66: =+IF(SUM(FB3:FB65)-SUM(FC3:FC65)<0,SUM(FB3:FB65)-SUM(FC3:FC65),"0") -> 0 | FF66: =+IF(SUM(FF3:FF65)-SUM(FG3:FG65)>0,SUM(FF3:FF65)-SUM(FG3:FG65),"0") -> 0 | FG66: =+IF(SUM(FF3:FF65)-SUM(FG3:FG65)<0,SUM(FF3:FF65)-SUM(FG3:FG65),"0") -> 0 | FJ66: =+IF(SUM(FJ3:FJ65)-SUM(FK3:FK65)>0,SUM(FJ3:FJ65)-SUM(FK3:FK65),"0") -> 0 | FK66: =+IF(SUM(FJ3:FJ65)-SUM(FK3:FK65)<0,SUM(FJ3:FJ65)-SUM(FK3:FK65),"0") -> 0 | FN66: =+IF(SUM(FN3:FN65)-SUM(FO3:FO65)>0,SUM(FN3:FN65)-SUM(FO3:FO65),"0") -> 0 | FO66: =+IF(SUM(FN3:FN65)-SUM(FO3:FO65)<0,SUM(FN3:FN65)-SUM(FO3:FO65),"0") -> 0 | FR66: =+IF(SUM(FR3:FR65)-SUM(FS3:FS65)>0,SUM(FR3:FR65)-SUM(FS3:FS65),"0") -> 0 | FS66: =+IF(SUM(FR3:FR65)-SUM(FS3:FS65)<0,SUM(FR3:FR65)-SUM(FS3:FS65),"0") -> 0 | FV66: =+IF(SUM(FV3:FV65)-SUM(FW3:FW65)>0,SUM(FV3:FV65)-SUM(FW3:FW65),"0") -> 0 | FW66: =+IF(SUM(FV3:FV65)-SUM(FW3:FW65)<0,SUM(FV3:FV65)-SUM(FW3:FW65),"0") -> 0 | FZ66: =+IF(SUM(FZ3:FZ65)-SUM(GA3:GA65)>0,SUM(FZ3:FZ65)-SUM(GA3:GA65),"0") -> 0 | GA66: =+IF(SUM(FZ3:FZ65)-SUM(GA3:GA65)<0,SUM(FZ3:FZ65)-SUM(GA3:GA65),"0") -> 0 | GD66: =+IF(SUM(GD3:GD65)-SUM(GE3:GE65)>0,SUM(GD3:GD65)-SUM(GE3:GE65),"0") -> 0 | GE66: =+IF(SUM(GD3:GD65)-SUM(GE3:GE65)<0,SUM(GD3:GD65)-SUM(GE3:GE65),"0") -> 0 | GH66: =+IF(SUM(GH3:GH65)-SUM(GI3:GI65)>0,SUM(GH3:GH65)-SUM(GI3:GI65),"0") -> 0 | GI66: =+IF(SUM(GH3:GH65)-SUM(GI3:GI65)<0,SUM(GH3:GH65)-SUM(GI3:GI65),"0") -> 0 | GL66: =+IF(SUM(GL3:GL65)-SUM(GM3:GM65)>0,SUM(GL3:GL65)-SUM(GM3:GM65),"0") -> 0 | GM66: =+IF(SUM(GL3:GL65)-SUM(GM3:GM65)<0,SUM(GL3:GL65)-SUM(GM3:GM65),"0") -> 0 | GP66: =+IF(SUM(GP3:GP65)-SUM(GQ3:GQ65)>0,SUM(GP3:GP65)-SUM(GQ3:GQ65),"0") -> 0 | GQ66: =+IF(SUM(GP3:GP65)-SUM(GQ3:GQ65)<0,SUM(GP3:GP65)-SUM(GQ3:GQ65),"0") -> 0 | GT66: =+IF(SUM(GT3:GT65)-SUM(GU3:GU65)>0,SUM(GT3:GT65)-SUM(GU3:GU65),"0") -> 0 | GU66: =+IF(SUM(GT3:GT65)-SUM(GU3:GU65)<0,SUM(GT3:GT65)-SUM(GU3:GU65),"0") -> 0
DU67: =+DV2 -> 0 | DV67: =+DV66+DW66 -> 0 | DY67: =+DZ2 -> 0 | DZ67: =+DZ66+EA66 -> 0 | EC67: =+ED2 -> 0 | ED67: =+ED66+EE66 -> 0 | EG67: =+EH2 -> 0 | EH67: =+EH66+EI66 -> 0 | EK67: =+EL2 -> 0 | EL67: =+EL66+EM66 -> 0 | EO67: =+EP2 -> 0 | EP67: =+EP66+EQ66 -> 0 | ES67: =+ET2 -> 0 | ET67: =+ET66+EU66 -> 0 | EW67: =+EX2 -> 0 | EX67: =+EX66+EY66 -> 0 | FA67: =+FB2 -> 0 | FB67: =+FB66+FC66 -> 0 | FE67: =+FF2 -> 0 | FF67: =+FF66+FG66 -> 0 | FI67: =+FJ2 -> 0 | FJ67: =+FJ66+FK66 -> 0 | FM67: =+FN2 -> 0 | FN67: =+FN66+FO66 -> 0 | FQ67: =+FR2 -> 0 | FR67: =+FR66+FS66 -> 0 | FU67: =+FV2 -> 0 | FV67: =+FV66+FW66 -> 0 | FY67: =+FZ2 -> 0 | FZ67: =+FZ66+GA66 -> 0 | GC67: =+GD2 -> 0 | GD67: =+GD66+GE66 -> 0 | GG67: =+GH2 -> 0 | GH67: =+GH66+GI66 -> 0 | GK67: =+GL2 -> 0 | GL67: =+GL66+GM66 -> 0 | GO67: =+GP2 -> 0 | GP67: =+GP66+GQ66 -> 0 | GS67: =+GT2 -> 0 | GT67: =+GT66+GU66 -> 0

Sheet ALL
D3: Adjusted trial balance month1 | J3: Adjusted trial balance month2
D4: 44592 | J4: 44620
D5: Cash | F5: =+'t-accounts month 1'!B35 -> 113825 | J5: Cash | L5: =+'t-accounts month 2'!B30 -> 155875
D7: Padel equipment | F7: =+'t-accounts month 1'!CA35 -> 400 | J7: Padel Equipment | L7: 400
D9: Padel equipment inventory | F9: ='t-accounts month 1'!R35 -> 2525 | J9: Padel equipment inventory | L9: 455
D11: Padel equipment for coaches | F11: =+'t-accounts month 1'!V35 -> 250 | J11: Padel equipment for coaches | L11: 250
D13: Courts | F13: =+'t-accounts month 1'!AE35 -> 120000 | J13: Courts | L13: 120000
D15: Capital stock | G15: =+'t-accounts month 1'!G35 -> 200000 | J15: Capital stock | M15: 200000
D17: Accumulated depreciation | G17: =+'t-accounts month 1'!CJ35 -> 500 | J17: Retained earnings | M17: 36000
D19: Court revenue from members | G19: =+'t-accounts month 1'!AJ35 -> 14700 | J19: Accumulated depreciation | M19: =+'t-accounts month 2'!CM30 -> 1000
D21: Court revenue | G21: =+'t-accounts month 1'!AN35 -> 14000 | J21: Machine revenue | M21: 300
D23: Equipment loaned revenue | G23: =+'t-accounts month 1'!AR35 -> 1100 | J23: Rackets sold | M23: 350
D25: Rackets sold revenue | G25: =+'t-accounts month 1'!BP35 -> 1800 | J25: Balls sold | M25: 100
D27: Balls sold revenue | G27: =+'t-accounts month 1'!BT35 -> 800 | J27: Equipment loaned revenue | M27: 1100
D29: Training revenue | G29: =+'t-accounts month 1'!BD35 -> 16200 | J29: Court member revenue | M29: 14700
D31: Vending machine revenue | G31: =+'t-accounts month 1'!BH35 -> 300 | J31: Court revenue | M31: 14000
D33: Membership revenue | G33: =+'t-accounts month 1'!BL35 -> 12000 | J33: Training revenue | M33: 16200
D35: Rent expense | F35: =+'t-accounts month 1'!AU35 -> 5700 | J35: Membership revenue | M35: 15000
D37: Salary expense | F37: =+'t-accounts month 1'!AY35 -> 13700
D39: Public service expense | F39: =+'t-accounts month 1'!BW35 -> 4500
D41: Depreciation expense | F41: =+'t-accounts month 1'!CE35 -> 500
D43: TOTAL | F43: =SUM(F5:F41) -> 261400 | G43: =SUM(G15:G33) -> 261400 | J43: Rent expense | L43: 5700
D45: Reial Club De Padel Roldans | J45: Salary expense | L45: 13700
D46: Icome statement
D47: 44592 | J47: Depreciation expense | L47: 500
D48: Revenue
D49: Court member revenue | G49: =G19 -> 14700
J50: TOTAL | L50: 178600 | M50: 62750
D51: Court revenue | G51: =G21 -> 14000
D53: Equipment loaned revenue | G53: =G23 -> 1100 | J53: TOTAL | L53: =SUM(L5:L47) -> 296880 | M53: =SUM(M6:M49) -> 298750
D55: Rackets sold revenue | G55: =G25 -> 1800 | J55: Reial Club De Padel Roldans
J56: Icome statement
D57: Balls sold revenue | G57: =G27 -> 800 | J57: 44620
J58: Machine revenue | M58: 300
D59: Training revenue | G59: =G29 -> 16200
J60: Rackets sold | M60: 350
D61: Vending machine revenue | G61: =G31 -> 300
J62: Balls sold | M62: 100
D63: Membership revenue | G63: =G33 -> 12000
J64: Equipment loaned | M64: 1100
...

Sheet Balance of Account
B1: Reial Club De Pàdel Roldans
B2: Balance Sheet
B3: Month: | C3: 44592 | D3: 44593
B5: ASSETS | E5: LIABILITIES & OWNERS EQUITY
B6: CURRENT ASSETS | E6: CURRENT LIABILITIES
B7: Cash | C7: 113825 | E7: Account Payable | F7: =+#REF! -> #REF!
B8: Accounts Receivable | E8: Notes Payable | F8: =+#REF! -> #REF!
E9: Income Taxes Payable
B10: Inventory (Tools & Equipment) | E10: Accrued Salaries and Wages
E11: Unearned Revenues
E12: Current portion of Long-Term Debt
B13: TOTAL CURRENT ASSETS | C13: =+SUM(C7:C12) -> 113825 | E13: TOTAL CURRENT LIABILITIES | F13: =+SUM(F7:F12) -> #REF!
B14: FIXED (LONG TERM ASSETS) | E14: LONG TERM LIABILITIES
B15: Paddle tennis courts | C15: 120000 | E15: Long-Term Debt
B16: Building rent | C16: 5700 | E16: Defferred Income Tax
E17: Other
E18: TOTAL LONG TERM LIABILITIES | F18: =+SUM(F15:F17) -> 0
B19: TOTAL FIXED (LONG TERM ASSETS) | C19: =+SUM(C14:C18) -> 125700 | E19: OWNERS EQUITY
B20: OTHER ASSETS | E20: Capital Stock | F20: 200000
B21: Defferred income tax | E21: Retained Earnings | F21: =+#REF! -> #REF!
B22: Others | E22: Dividends | F22: =-#REF! -> #REF!
B23: TOTAL OTHER ASSETS | C23: =+SUM(C20:C22) -> 0 | E23: TOTAL OWNERS EQUITY | F23: =+SUM(F20:F22) -> #REF!
C25: =+C23+C19+C13 -> 239525 | F25: =+F23+F18+F13 -> #REF!
B27: =+IF((C13+C19+C23)=(F13+F18+F23),"This Financial Statement is BALANCED","PLEASE CHECK!!! THERE IS SOMETHING MISSING") -> #REF!
G33: 0
